<robot name="quadruped_robot">

	<!-- * * * Link Definitions * * * -->

 	<link name="base">
		<visual>
		    <origin xyz="0 0 0"/>
			<geometry>
				<box size="0.5 0.25 0.1"/>
			</geometry>
		</visual>	
	</link>

	<link name="up_leg_fl">
		<visual>
		    <origin xyz="0 0.15 -0.05"/>
			<geometry>
				<box size="0.05 0.05 0.2"/>
			</geometry>
		</visual>	
	</link>
	
	<link name="up_leg_fr">
		<visual>
		    <origin xyz="0 -0.15 -0.05"/>
			<geometry>
				<box size="0.05 0.05 0.2"/>
			</geometry>
		</visual>	
	</link>
	
	<link name="up_leg_br">
		<visual>
		    <origin xyz="0 -0.15 -0.05"/>
			<geometry>
				<box size="0.05 0.05 0.2"/>
			</geometry>
		</visual>	
	</link>

	<link name="up_leg_bl">
		<visual>
		    <origin xyz="0 0.15 -0.05"/>
			<geometry>
				<box size="0.05 0.05 0.2"/>
			</geometry>
		</visual>	
	</link>
	

	<link name="bottom_leg_fl">
		<visual>
		    <origin xyz="0 0 -0.1"/>
			<geometry>
				<box size="0.05 0.05 0.2"/>
			</geometry>
		</visual>	
	</link>

	<link name="bottom_leg_fr">
		<visual>
		    <origin xyz="0 0 -0.1"/>
			<geometry>
				<box size="0.05 0.05 0.2"/>
			</geometry>
		</visual>	
	</link>

	<link name="bottom_leg_bl">
		<visual>
		    <origin xyz="0 0 -0.1"/>
			<geometry>
				<box size="0.05 0.05 0.2"/>
			</geometry>
		</visual>	
	</link>

	<link name="bottom_leg_br">
		<visual>
		    <origin xyz="0 0 -0.1"/>
			<geometry>
				<box size="0.05 0.05 0.2"/>
			</geometry>
		</visual>	
	</link>
	<!-- * * * Joint Definitions * * * -->
	
	<joint name="up_fl" type="revolute">
		<parent link="base"/>
		<child link="up_leg_fl"/>
      	<origin xyz="0.2 0 0"/>
      	<axis xyz="0 -1 0"/>
	</joint>

	<joint name="up_fr" type="revolute">
		<parent link="base"/>
		<child link="up_leg_fr"/>
      	<origin xyz="0.2 0 0"/>
      	<axis xyz="0 -1 0"/>
	</joint>

	<joint name="up_bl" type="revolute">
		<parent link="base"/>
		<child link="up_leg_bl"/>
      	<origin xyz="-0.2 0 0"/>
      	<axis xyz="0 -1 0"/>
	</joint>

	<joint name="up_br" type="revolute">
		<parent link="base"/>
		<child link="up_leg_br"/>
      	<origin xyz="-0.2 0 0"/>
      	<axis xyz="0 -1 0"/>
	</joint>

	<joint name="bottom_fl" type="revolute">
		<parent link="up_leg_fl"/>
		<child link="bottom_leg_fl"/>
      	<origin xyz="0 0.15 -0.15"/>
      	<axis xyz="0 -1 0"/>
	</joint>

	<joint name="bottom_fr" type="revolute">
		<parent link="up_leg_fr"/>
		<child link="bottom_leg_fr"/>
      	<origin xyz="0 -0.15 -0.15"/>
      	<axis xyz="0 -1 0"/>
	</joint>

	<joint name="bottom_bl" type="revolute">
		<parent link="up_leg_bl"/>
		<child link="bottom_leg_bl"/>
      	<origin xyz="0 0.15 -0.15"/>
      	<axis xyz="0 -1 0"/>
	</joint>

	<joint name="bottom_br" type="revolute">
		<parent link="up_leg_br"/>
		<child link="bottom_leg_br"/>
      	<origin xyz="0 -0.15 -0.15"/>
      	<axis xyz="0 -1 0"/>
	</joint>
</robot>
