<?xml version="1.0" ?>
<!-- =================================================================================== -->
<!-- |    This document was autogenerated by xacro from description/quadruped_robot.xacro | -->
<!-- |    EDITING THIS FILE BY HAND IS NOT RECOMMENDED                                 | -->
<!-- =================================================================================== -->
<robot name="quadruped_robot">
  <material name="black">
    <color rgba="0.0 0.0 0.0 1.0"/>
  </material>
  <material name="blue">
    <color rgba="0.0 0.0 0.8 1.0"/>
  </material>
  <material name="green">
    <color rgba="0.0 0.8 0.0 1.0"/>
  </material>
  <material name="grey">
    <color rgba="0.2 0.2 0.2 1.0"/>
  </material>
  <material name="orange">
    <color rgba="1.0 0.4235294117647059 0.0392156862745098 1.0"/>
  </material>
  <material name="brown">
    <color rgba="0.8705882352941177 0.8117647058823529 0.7647058823529411 1.0"/>
  </material>
  <material name="red">
    <color rgba="0.8 0.0 0.0 1.0"/>
  </material>
  <material name="white">
    <color rgba="1.0 1.0 1.0 1.0"/>
  </material>
  <!-- see https://secure.wikimedia.org/wikipedia/en/wiki/List_of_moment_of_inertia_tensors -->
  <link name="base">
    <inertial>
      <mass value="1"/>
      <origin xyz="0 0 0"/>
      <inertia ixx="0.0" ixy="0.0" ixz="0.0" iyy="0.0" iyz="0.0" izz="0.0"/>
    </inertial>
    <visual>
      <origin xyz="0 0 0"/>
      <geometry>
        <box size="0.5 0.25 0.1"/>
      </geometry>
      <material name="grey"/>
    </visual>
    <collision>
      <origin xyz="0 0 0"/>
      <geometry>
        <box size="0.5 0.25 0.1"/>
      </geometry>
    </collision>
  </link>
  <link name="up_leg_fl">
    <inertial>
      <mass value="1"/>
      <origin xyz="0 0 0"/>
      <inertia ixx="0.0020833325" ixy="0.0" ixz="0.0" iyy="0.00020833325000000003" iyz="0.0" izz="0.00187499925"/>
    </inertial>
    <visual>
      <origin xyz="0 0.15 -0.05"/>
      <geometry>
        <box size="0.05 0.05 0.2"/>
      </geometry>
      <material name="grey"/>
    </visual>
    <collision>
      <origin xyz="0 0.15 -0.05"/>
      <geometry>
        <box size="0.05 0.05 0.2"/>
      </geometry>
    </collision>
  </link>
  <link name="up_leg_fr">
    <inertial>
      <mass value="1"/>
      <origin xyz="0 0 0"/>
      <inertia ixx="0.0020833325" ixy="0.0" ixz="0.0" iyy="0.00020833325000000003" iyz="0.0" izz="0.00187499925"/>
    </inertial>
    <visual>
      <origin xyz="0 -0.15 -0.05"/>
      <geometry>
        <box size="0.05 0.05 0.2"/>
      </geometry>
      <material name="grey"/>
    </visual>
    <collision>
      <origin xyz="0 -0.15 -0.05"/>
      <geometry>
        <box size="0.05 0.05 0.2"/>
      </geometry>
    </collision>
  </link>
  <link name="up_leg_bl">
    <inertial>
      <mass value="1"/>
      <origin xyz="0 0 0"/>
      <inertia ixx="0.0020833325" ixy="0.0" ixz="0.0" iyy="0.00020833325000000003" iyz="0.0" izz="0.00187499925"/>
    </inertial>
    <visual>
      <origin xyz="0 0.15 -0.05"/>
      <geometry>
        <box size="0.05 0.05 0.2"/>
      </geometry>
      <material name="grey"/>
    </visual>
    <collision>
      <origin xyz="0 0.15 -0.05"/>
      <geometry>
        <box size="0.05 0.05 0.2"/>
      </geometry>
    </collision>
  </link>
  <link name="up_leg_br">
    <inertial>
      <mass value="1"/>
      <origin xyz="0 0 0"/>
      <inertia ixx="0.0020833325" ixy="0.0" ixz="0.0" iyy="0.00020833325000000003" iyz="0.0" izz="0.00187499925"/>
    </inertial>
    <visual>
      <origin xyz="0 -0.15 -0.05"/>
      <geometry>
        <box size="0.05 0.05 0.2"/>
      </geometry>
      <material name="grey"/>
    </visual>
    <collision>
      <origin xyz="0 -0.15 -0.05"/>
      <geometry>
        <box size="0.05 0.05 0.2"/>
      </geometry>
    </collision>
  </link>
  <link name="bottom_leg_fl">
    <inertial>
      <mass value="1"/>
      <origin xyz="0 0 0"/>
      <inertia ixx="0.0008333330000000001" ixy="0.0" ixz="0.0" iyy="0.0008333330000000001" iyz="0.0" izz="0.0"/>
    </inertial>
    <visual>
      <origin xyz="0 0 -0.1"/>
      <geometry>
        <box size="0.05 0.05 0.2"/>
      </geometry>
      <material name="grey"/>
    </visual>
    <collision>
      <origin xyz="0 0 -0.1"/>
      <geometry>
        <box size="0.05 0.05 0.2"/>
      </geometry>
    </collision>
  </link>
  <link name="bottom_leg_fr">
    <inertial>
      <mass value="1"/>
      <origin xyz="0 0 0"/>
      <inertia ixx="0.0008333330000000001" ixy="0.0" ixz="0.0" iyy="0.0008333330000000001" iyz="0.0" izz="0.0"/>
    </inertial>
    <visual>
      <origin xyz="0 0 -0.1"/>
      <geometry>
        <box size="0.05 0.05 0.2"/>
      </geometry>
      <material name="grey"/>
    </visual>
    <collision>
      <origin xyz="0 0 -0.1"/>
      <geometry>
        <box size="0.05 0.05 0.2"/>
      </geometry>
    </collision>
  </link>
  <link name="bottom_leg_bl">
    <inertial>
      <mass value="1"/>
      <origin xyz="0 0 0"/>
      <inertia ixx="0.0008333330000000001" ixy="0.0" ixz="0.0" iyy="0.0008333330000000001" iyz="0.0" izz="0.0"/>
    </inertial>
    <visual>
      <origin xyz="0 0 -0.1"/>
      <geometry>
        <box size="0.05 0.05 0.2"/>
      </geometry>
      <material name="grey"/>
    </visual>
    <collision>
      <origin xyz="0 0 -0.1"/>
      <geometry>
        <box size="0.05 0.05 0.2"/>
      </geometry>
    </collision>
  </link>
  <link name="bottom_leg_br">
    <inertial>
      <mass value="1"/>
      <origin xyz="0 0 0"/>
      <inertia ixx="0.0008333330000000001" ixy="0.0" ixz="0.0" iyy="0.0008333330000000001" iyz="0.0" izz="0.0"/>
    </inertial>
    <visual>
      <origin xyz="0 0 -0.1"/>
      <geometry>
        <box size="0.05 0.05 0.2"/>
      </geometry>
      <material name="grey"/>
    </visual>
    <collision>
      <origin xyz="0 0 -0.1"/>
      <geometry>
        <box size="0.05 0.05 0.2"/>
      </geometry>
    </collision>
  </link>
  <joint name="up_fl" type="revolute">
    <parent link="base"/>
    <child link="up_leg_fl"/>
    <origin xyz="0.2 0 0"/>
    <axis xyz="0 -1 0"/>
    <limit effort="100" lower="-3.14" upper="3.14" velocity="0.1"/>
    <dynamics damping="0.1" friction="0.1"/>
  </joint>
  <joint name="up_fr" type="revolute">
    <parent link="base"/>
    <child link="up_leg_fr"/>
    <origin xyz="0.2 0 0"/>
    <axis xyz="0 -1 0"/>
    <limit effort="100" lower="-3.14" upper="3.14" velocity="0.1"/>
    <dynamics damping="0.1" friction="0.1"/>
  </joint>
  <joint name="up_bl" type="revolute">
    <parent link="base"/>
    <child link="up_leg_bl"/>
    <origin xyz="-0.2 0 0"/>
    <axis xyz="0 -1 0"/>
    <limit effort="100" lower="-3.14" upper="3.14" velocity="0.1"/>
    <dynamics damping="0.1" friction="0.1"/>
  </joint>
  <joint name="up_br" type="revolute">
    <parent link="base"/>
    <child link="up_leg_br"/>
    <origin xyz="-0.2 0 0"/>
    <axis xyz="0 -1 0"/>
    <limit effort="100" lower="-3.14" upper="3.14" velocity="0.1"/>
    <dynamics damping="0.1" friction="0.1"/>
  </joint>
  <joint name="bottom_fl" type="revolute">
    <parent link="up_leg_fl"/>
    <child link="bottom_leg_fl"/>
    <origin xyz="0 0.15 -0.15"/>
    <axis xyz="0 -1 0"/>
    <limit effort="100" lower="-3.14" upper="3.14" velocity="0.1"/>
    <dynamics damping="0.1" friction="0.1"/>
  </joint>
  <joint name="bottom_fr" type="revolute">
    <parent link="up_leg_fr"/>
    <child link="bottom_leg_fr"/>
    <origin xyz="0 -0.15 -0.15"/>
    <axis xyz="0 -1 0"/>
    <limit effort="100" lower="-3.14" upper="3.14" velocity="0.1"/>
    <dynamics damping="0.1" friction="0.1"/>
  </joint>
  <joint name="bottom_bl" type="revolute">
    <parent link="up_leg_bl"/>
    <child link="bottom_leg_bl"/>
    <origin xyz="0 0.15 -0.15"/>
    <axis xyz="0 -1 0"/>
    <limit effort="100" lower="-3.14" upper="3.14" velocity="0.1"/>
    <dynamics damping="0.1" friction="0.1"/>
  </joint>
  <joint name="bottom_br" type="revolute">
    <parent link="up_leg_br"/>
    <child link="bottom_leg_br"/>
    <origin xyz="0 -0.15 -0.15"/>
    <axis xyz="0 -1 0"/>
    <limit effort="100" lower="-3.14" upper="3.14" velocity="0.1"/>
    <dynamics damping="0.1" friction="0.1"/>
  </joint>
</robot>
